Workbook

Sheet Admin
A1: PREPARED BY | B1: RANK | C1: Initials
A3: APPROVED BY SUPERVISOR | B3: RANK
A5: NAME (Last, First, Middle Initial) | B5: RANK | C5: M/F | D5: AGE | E5: HEIGHT (to nearest 0.50 inch) | F5: WEIGHT (to nearest pound) | G5: 540? | H5: MAX Weight | I5: Pass/Needs Tape | J5: FIRST | K5: SECOND | L5: THIRD | M5: AVERAGE (to nearest 0.50 in.) | N5: BODY FAT % (Figure B-1/B-2) | O5: EQUATION | P5: MAX BODY FAT % | Q5: Pass/Fail | R5: PREPARED BY | S5: RANK | T5: APPROVED BY SUPERVISOR | U5: RANK
H6: =IF(OR(Admin!E6="", Admin!D6=""), "", IF(Admin!C6="M", INDEX('Table B-1'!$C$9:$AX$31, MATCH(Admin!E6, 'Table B-1'!$A$9:$A$31, 0), MATCH(MIN(40,Admin!D6), 'Table B-1'!$C$4:$Z$4, 1)), IF(Admin!C6="F", INDEX('Table B-1'!$AA$9:$AX$31, MATCH(Admin!E6, 'Table B-1'!$A$9:$A$31, 0), MATCH(MIN(40,Admin!D6), 'Table B-1'!$AA$4:$AX$4, 1)), "" ) ) ) | I6: =IF(F6="", "", IF(F6>H6, "Needs Tape", IF(F6<=H6, "Pass", ""))) | M6: =IF(OR(ABS(J6-K6)>1, ABS(K6-L6)>1, ABS(J6-L6)>1), "Measurements differ by more than 1 inch", IF(OR(J6="", K6="", L6=""), "", ROUND(AVERAGE(J6, K6, L6)*2, 0)/2) ) | N6: =IF(OR(Admin!F6="", Admin!M6=""), "", IF(Admin!C6="M", IFERROR(INDEX('Figure B-1 Male'!$C$4:$AJ$164, MATCH(Admin!F6, 'Figure B-1 Male'!$B$4:$B$164, 0), MATCH(Admin!M6, 'Figure B-1 Male'!$C$3:$AJ$3, 1)) / 100, ""), IF(Admin!C6="F", IFERROR(INDEX('Figure B-2 Female'!$C$4:$AJ$164, MATCH(Admin!F6, 'Figure B-2 Female'!$B$4:$B$164, 0), MATCH(Admin!M6, 'Figure B-2 Female'!$C$3:$AJ$3, 1)) / 100, ""), "" ) ) ) | O6: =IF(OR(F6="", M6=""), "", IF(Admin!C6="M", (-26.97 - (0.12 * F6) + (1.99 * M6)) / 100, IF(Admin!C6="F", (-9.15 - (0.015 * F6) + (1.27 * M6)) / 100, "" ) ) ) | P6: =IF(OR(Admin!I6="Pass", Admin!I6=""), "", IF(Admin!D6="", "", IF(Admin!C6="M", INDEX('Table B-2'!$D$7:$D$30, MATCH(MIN(40, Admin!D6), 'Table B-2'!$C$7:$C$30, 0)), IF(Admin!C6="F", INDEX('Table B-2'!$F$7:$F$30, MATCH(MIN(40, Admin!D6), 'Table B-2'!$E$7:$E$30, 0)), "" ) ) ) ) | Q6: =IF(OR(O6="", P6=""), "", IF(O6>P6, "Fail Tape", IF(O6<=P6, "Pass", "")) )
H7: =IF(OR(Admin!E7="", Admin!D7=""), "", IF(Admin!C7="M", INDEX('Table B-1'!$C$9:$AX$31, MATCH(Admin!E7, 'Table B-1'!$A$9:$A$31, 0), MATCH(MIN(40,Admin!D7), 'Table B-1'!$C$4:$Z$4, 1)), IF(Admin!C7="F", INDEX('Table B-1'!$AA$9:$AX$31, MATCH(Admin!E7, 'Table B-1'!$A$9:$A$31, 0), MATCH(MIN(40,Admin!D7), 'Table B-1'!$AA$4:$AX$4, 1)), "" ) ) ) | I7: =IF(F7="", "", IF(F7>H7, "Needs Tape", IF(F7<=H7, "Pass", ""))) | M7: =IF(OR(ABS(J7-K7)>1, ABS(K7-L7)>1, ABS(J7-L7)>1), "Measurements differ by more than 1 inch", IF(OR(J7="", K7="", L7=""), "", ROUND(AVERAGE(J7, K7, L7)*2, 0)/2) ) | N7: =IF(OR(Admin!F7="", Admin!M7=""), "", IF(Admin!C7="M", IFERROR(INDEX('Figure B-1 Male'!$C$4:$AJ$164, MATCH(Admin!F7, 'Figure B-1 Male'!$B$4:$B$164, 0), MATCH(Admin!M7, 'Figure B-1 Male'!$C$3:$AJ$3, 1)) / 100, ""), IF(Admin!C7="F", IFERROR(INDEX('Figure B-2 Female'!$C$4:$AJ$164, MATCH(Admin!F7, 'Figure B-2 Female'!$B$4:$B$164, 0), MATCH(Admin!M7, 'Figure B-2 Female'!$C$3:$AJ$3, 1)) / 100, ""), "" ) ) ) | O7: =IF(OR(F7="", M7=""), "", IF(Admin!C7="M", (-26.97 - (0.12 * F7) + (1.99 * M7)) / 100, IF(Admin!C7="F", (-9.15 - (0.015 * F7) + (1.27 * M7)) / 100, "" ) ) ) | P7: =IF(OR(Admin!I7="Pass", Admin!I7=""), "", IF(Admin!D7="", "", IF(Admin!C7="M", INDEX('Table B-2'!$D$7:$D$30, MATCH(MIN(40, Admin!D7), 'Table B-2'!$C$7:$C$30, 0)), IF(Admin!C7="F", INDEX('Table B-2'!$F$7:$F$30, MATCH(MIN(40, Admin!D7), 'Table B-2'!$E$7:$E$30, 0)), "" ) ) ) ) | Q7: =IF(OR(N7="", P7=""), "", IF(N7>P7, "Fail Tape", IF(N7<=P7, "Pass", "")) )
H8: =IF(OR(Admin!E8="", Admin!D8=""), "", IF(Admin!C8="M", INDEX('Table B-1'!$C$9:$AX$31, MATCH(Admin!E8, 'Table B-1'!$A$9:$A$31, 0), MATCH(MIN(40,Admin!D8), 'Table B-1'!$C$4:$Z$4, 1)), IF(Admin!C8="F", INDEX('Table B-1'!$AA$9:$AX$31, MATCH(Admin!E8, 'Table B-1'!$A$9:$A$31, 0), MATCH(MIN(40,Admin!D8), 'Table B-1'!$AA$4:$AX$4, 1)), "" ) ) ) | I8: =IF(F8="", "", IF(F8>H8, "Needs Tape", IF(F8<=H8, "Pass", ""))) | M8: =IF(OR(ABS(J8-K8)>1, ABS(K8-L8)>1, ABS(J8-L8)>1), "Measurements differ by more than 1 inch", IF(OR(J8="", K8="", L8=""), "", ROUND(AVERAGE(J8, K8, L8)*2, 0)/2) ) | N8: =IF(OR(Admin!F8="", Admin!M8=""), "", IF(Admin!C8="M", IFERROR(INDEX('Figure B-1 Male'!$C$4:$AJ$164, MATCH(Admin!F8, 'Figure B-1 Male'!$B$4:$B$164, 0), MATCH(Admin!M8, 'Figure B-1 Male'!$C$3:$AJ$3, 1)) / 100, ""), IF(Admin!C8="F", IFERROR(INDEX('Figure B-2 Female'!$C$4:$AJ$164, MATCH(Admin!F8, 'Figure B-2 Female'!$B$4:$B$164, 0), MATCH(Admin!M8, 'Figure B-2 Female'!$C$3:$AJ$3, 1)) / 100, ""), "" ) ) ) | O8: =IF(OR(F8="", M8=""), "", IF(Admin!C8="M", (-26.97 - (0.12 * F8) + (1.99 * M8)) / 100, IF(Admin!C8="F", (-9.15 - (0.015 * F8) + (1.27 * M8)) / 100, "" ) ) ) | P8: =IF(OR(Admin!I8="Pass", Admin!I8=""), "", IF(Admin!D8="", "", IF(Admin!C8="M", INDEX('Table B-2'!$D$7:$D$30, MATCH(MIN(40, Admin!D8), 'Table B-2'!$C$7:$C$30, 0)), IF(Admin!C8="F", INDEX('Table B-2'!$F$7:$F$30, MATCH(MIN(40, Admin!D8), 'Table B-2'!$E$7:$E$30, 0)), "" ) ) ) ) | Q8: =IF(OR(N8="", P8=""), "", IF(N8>P8, "Fail Tape", IF(N8<=P8, "Pass", "")) )
H9: =IF(OR(Admin!E9="", Admin!D9=""), "", IF(Admin!C9="M", INDEX('Table B-1'!$C$9:$AX$31, MATCH(Admin!E9, 'Table B-1'!$A$9:$A$31, 0), MATCH(MIN(40,Admin!D9), 'Table B-1'!$C$4:$Z$4, 1)), IF(Admin!C9="F", INDEX('Table B-1'!$AA$9:$AX$31, MATCH(Admin!E9, 'Table B-1'!$A$9:$A$31, 0), MATCH(MIN(40,Admin!D9), 'Table B-1'!$AA$4:$AX$4, 1)), "" ) ) ) | I9: =IF(F9="", "", IF(F9>H9, "Needs Tape", IF(F9<=H9, "Pass", ""))) | M9: =IF(OR(ABS(J9-K9)>1, ABS(K9-L9)>1, ABS(J9-L9)>1), "Measurements differ by more than 1 inch", IF(OR(J9="", K9="", L9=""), "", ROUND(AVERAGE(J9, K9, L9)*2, 0)/2) ) | N9: =IF(OR(Admin!F9="", Admin!M9=""), "", IF(Admin!C9="M", IFERROR(INDEX('Figure B-1 Male'!$C$4:$AJ$164, MATCH(Admin!F9, 'Figure B-1 Male'!$B$4:$B$164, 0), MATCH(Admin!M9, 'Figure B-1 Male'!$C$3:$AJ$3, 1)) / 100, ""), IF(Admin!C9="F", IFERROR(INDEX('Figure B-2 Female'!$C$4:$AJ$164, MATCH(Admin!F9, 'Figure B-2 Female'!$B$4:$B$164, 0), MATCH(Admin!M9, 'Figure B-2 Female'!$C$3:$AJ$3, 1)) / 100, ""), "" ) ) ) | O9: =IF(OR(F9="", M9=""), "", IF(Admin!C9="M", (-26.97 - (0.12 * F9) + (1.99 * M9)) / 100, IF(Admin!C9="F", (-9.15 - (0.015 * F9) + (1.27 * M9)) / 100, "" ) ) ) | P9: =IF(OR(Admin!I9="Pass", Admin!I9=""), "", IF(Admin!D9="", "", IF(Admin!C9="M", INDEX('Table B-2'!$D$7:$D$30, MATCH(MIN(40, Admin!D9), 'Table B-2'!$C$7:$C$30, 0)), IF(Admin!C9="F", INDEX('Table B-2'!$F$7:$F$30, MATCH(MIN(40, Admin!D9), 'Table B-2'!$E$7:$E$30, 0)), "" ) ) ) ) | Q9: =IF(OR(N9="", P9=""), "", IF(N9>P9, "Fail Tape", IF(N9<=P9, "Pass", "")) )
H10: =IF(OR(Admin!E10="", Admin!D10=""), "", IF(Admin!C10="M", INDEX('Table B-1'!$C$9:$AX$31, MATCH(Admin!E10, 'Table B-1'!$A$9:$A$31, 0), MATCH(MIN(40,Admin!D10), 'Table B-1'!$C$4:$Z$4, 1)), IF(Admin!C10="F", INDEX('Table B-1'!$AA$9:$AX$31, MATCH(Admin!E10, 'Table B-1'!$A$9:$A$31, 0), MATCH(MIN(40,Admin!D10), 'Table B-1'!$AA$4:$AX$4, 1)), "" ) ) ) | I10: =IF(F10="", "", IF(F10>H10, "Needs Tape", IF(F10<=H10, "Pass", ""))) | M10: =IF(OR(ABS(J10-K10)>1, ABS(K10-L10)>1, ABS(J10-L10)>1), "Measurements differ by more than 1 inch", IF(OR(J10="", K10="", L10=""), "", ROUND(AVERAGE(J10, K10, L10)*2, 0)/2) ) | N10: =IF(OR(Admin!F10="", Admin!M10=""), "", IF(Admin!C10="M", IFERROR(INDEX('Figure B-1 Male'!$C$4:$AJ$164, MATCH(Admin!F10, 'Figure B-1 Male'!$B$4:$B$164, 0), MATCH(Admin!M10, 'Figure B-1 Male'!$C$3:$AJ$3, 1)) / 100, ""), IF(Admin!C10="F", IFERROR(INDEX('Figure B-2 Female'!$C$4:$AJ$164, MATCH(Admin!F10, 'Figure B-2 Female'!$B$4:$B$164, 0), MATCH(Admin!M10, 'Figure B-2 Female'!$C$3:$AJ$3, 1)) / 100, ""), "" ) ) ) | O10: =IF(OR(F10="", M10=""), "", IF(Admin!C10="M", (-26.97 - (0.12 * F10) + (1.99 * M10)) / 100, IF(Admin!C10="F", (-9.15 - (0.015 * F10) + (1.27 * M10)) / 100, "" ) ) ) | P10: =IF(OR(Admin!I10="Pass", Admin!I10=""), "", IF(Admin!D10="", "", IF(Admin!C10="M", INDEX('Table B-2'!$D$7:$D$30, MATCH(MIN(40, Admin!D10), 'Table B-2'!$C$7:$C$30, 0)), IF(Admin!C10="F", INDEX('Table B-2'!$F$7:$F$30, MATCH(MIN(40, Admin!D10), 'Table B-2'!$E$7:$E$30, 0)), "" ) ) ) ) | Q10: =IF(OR(N10="", P10=""), "", IF(N10>P10, "Fail Tape", IF(N10<=P10, "Pass", "")) )
H11: =IF(OR(Admin!E11="", Admin!D11=""), "", IF(Admin!C11="M", INDEX('Table B-1'!$C$9:$AX$31, MATCH(Admin!E11, 'Table B-1'!$A$9:$A$31, 0), MATCH(MIN(40,Admin!D11), 'Table B-1'!$C$4:$Z$4, 1)), IF(Admin!C11="F", INDEX('Table B-1'!$AA$9:$AX$31, MATCH(Admin!E11, 'Table B-1'!$A$9:$A$31, 0), MATCH(MIN(40,Admin!D11), 'Table B-1'!$AA$4:$AX$4, 1)), "" ) ) ) | I11: =IF(F11="", "", IF(F11>H11, "Needs Tape", IF(F11<=H11, "Pass", ""))) | M11: =IF(OR(ABS(J11-K11)>1, ABS(K11-L11)>1, ABS(J11-L11)>1), "Measurements differ by more than 1 inch", IF(OR(J11="", K11="", L11=""), "", ROUND(AVERAGE(J11, K11, L11)*2, 0)/2) ) | N11: =IF(OR(Admin!F11="", Admin!M11=""), "", IF(Admin!C11="M", IFERROR(INDEX('Figure B-1 Male'!$C$4:$AJ$164, MATCH(Admin!F11, 'Figure B-1 Male'!$B$4:$B$164, 0), MATCH(Admin!M11, 'Figure B-1 Male'!$C$3:$AJ$3, 1)) / 100, ""), IF(Admin!C11="F", IFERROR(INDEX('Figure B-2 Female'!$C$4:$AJ$164, MATCH(Admin!F11, 'Figure B-2 Female'!$B$4:$B$164, 0), MATCH(Admin!M11, 'Figure B-2 Female'!$C$3:$AJ$3, 1)) / 100, ""), "" ) ) ) | O11: =IF(OR(F11="", M11=""), "", IF(Admin!C11="M", (-26.97 - (0.12 * F11) + (1.99 * M11)) / 100, IF(Admin!C11="F", (-9.15 - (0.015 * F11) + (1.27 * M11)) / 100, "" ) ) ) | P11: =IF(OR(Admin!I11="Pass", Admin!I11=""), "", IF(Admin!D11="", "", IF(Admin!C11="M", INDEX('Table B-2'!$D$7:$D$30, MATCH(MIN(40, Admin!D11), 'Table B-2'!$C$7:$C$30, 0)), IF(Admin!C11="F", INDEX('Table B-2'!$F$7:$F$30, MATCH(MIN(40, Admin!D11), 'Table B-2'!$E$7:$E$30, 0)), "" ) ) ) ) | Q11: =IF(OR(N11="", P11=""), "", IF(N11>P11, "Fail Tape", IF(N11<=P11, "Pass", "")) )
H12: =IF(OR(Admin!E12="", Admin!D12=""), "", IF(Admin!C12="M", INDEX('Table B-1'!$C$9:$AX$31, MATCH(Admin!E12, 'Table B-1'!$A$9:$A$31, 0), MATCH(MIN(40,Admin!D12), 'Table B-1'!$C$4:$Z$4, 1)), IF(Admin!C12="F", INDEX('Table B-1'!$AA$9:$AX$31, MATCH(Admin!E12, 'Table B-1'!$A$9:$A$31, 0), MATCH(MIN(40,Admin!D12), 'Table B-1'!$AA$4:$AX$4, 1)), "" ) ) ) | I12: =IF(F12="", "", IF(F12>H12, "Needs Tape", IF(F12<=H12, "Pass", ""))) | M12: =IF(OR(ABS(J12-K12)>1, ABS(K12-L12)>1, ABS(J12-L12)>1), "Measurements differ by more than 1 inch", IF(OR(J12="", K12="", L12=""), "", ROUND(AVERAGE(J12, K12, L12)*2, 0)/2) ) | N12: =IF(OR(Admin!F12="", Admin!M12=""), "", IF(Admin!C12="M", IFERROR(INDEX('Figure B-1 Male'!$C$4:$AJ$164, MATCH(Admin!F12, 'Figure B-1 Male'!$B$4:$B$164, 0), MATCH(Admin!M12, 'Figure B-1 Male'!$C$3:$AJ$3, 1)) / 100, ""), IF(Admin!C12="F", IFERROR(INDEX('Figure B-2 Female'!$C$4:$AJ$164, MATCH(Admin!F12, 'Figure B-2 Female'!$B$4:$B$164, 0), MATCH(Admin!M12, 'Figure B-2 Female'!$C$3:$AJ$3, 1)) / 100, ""), "" ) ) ) | O12: =IF(OR(F12="", M12=""), "", IF(Admin!C12="M", (-26.97 - (0.12 * F12) + (1.99 * M12)) / 100, IF(Admin!C12="F", (-9.15 - (0.015 * F12) + (1.27 * M12)) / 100, "" ) ) ) | P12: =IF(OR(Admin!I12="Pass", Admin!I12=""), "", IF(Admin!D12="", "", IF(Admin!C12="M", INDEX('Table B-2'!$D$7:$D$30, MATCH(MIN(40, Admin!D12), 'Table B-2'!$C$7:$C$30, 0)), IF(Admin!C12="F", INDEX('Table B-2'!$F$7:$F$30, MATCH(MIN(40, Admin!D12), 'Table B-2'!$E$7:$E$30, 0)), "" ) ) ) ) | Q12: =IF(OR(N12="", P12=""), "", IF(N12>P12, "Fail Tape", IF(N12<=P12, "Pass", "")) )
H13: =IF(OR(Admin!E13="", Admin!D13=""), "", IF(Admin!C13="M", INDEX('Table B-1'!$C$9:$AX$31, MATCH(Admin!E13, 'Table B-1'!$A$9:$A$31, 0), MATCH(MIN(40,Admin!D13), 'Table B-1'!$C$4:$Z$4, 1)), IF(Admin!C13="F", INDEX('Table B-1'!$AA$9:$AX$31, MATCH(Admin!E13, 'Table B-1'!$A$9:$A$31, 0), MATCH(MIN(40,Admin!D13), 'Table B-1'!$AA$4:$AX$4, 1)), "" ) ) ) | I13: =IF(F13="", "", IF(F13>H13, "Needs Tape", IF(F13<=H13, "Pass", ""))) | M13: =IF(OR(ABS(J13-K13)>1, ABS(K13-L13)>1, ABS(J13-L13)>1), "Measurements differ by more than 1 inch", IF(OR(J13="", K13="", L13=""), "", ROUND(AVERAGE(J13, K13, L13)*2, 0)/2) ) | N13: =IF(OR(Admin!F13="", Admin!M13=""), "", IF(Admin!C13="M", IFERROR(INDEX('Figure B-1 Male'!$C$4:$AJ$164, MATCH(Admin!F13, 'Figure B-1 Male'!$B$4:$B$164, 0), MATCH(Admin!M13, 'Figure B-1 Male'!$C$3:$AJ$3, 1)) / 100, ""), IF(Admin!C13="F", IFERROR(INDEX('Figure B-2 Female'!$C$4:$AJ$164, MATCH(Admin!F13, 'Figure B-2 Female'!$B$4:$B$164, 0), MATCH(Admin!M13, 'Figure B-2 Female'!$C$3:$AJ$3, 1)) / 100, ""), "" ) ) ) | O13: =IF(OR(F13="", M13=""), "", IF(Admin!C13="M", (-26.97 - (0.12 * F13) + (1.99 * M13)) / 100, IF(Admin!C13="F", (-9.15 - (0.015 * F13) + (1.27 * M13)) / 100, "" ) ) ) | P13: =IF(OR(Admin!I13="Pass", Admin!I13=""), "", IF(Admin!D13="", "", IF(Admin!C13="M", INDEX('Table B-2'!$D$7:$D$30, MATCH(MIN(40, Admin!D13), 'Table B-2'!$C$7:$C$30, 0)), IF(Admin!C13="F", INDEX('Table B-2'!$F$7:$F$30, MATCH(MIN(40, Admin!D13), 'Table B-2'!$E$7:$E$30, 0)), "" ) ) ) ) | Q13: =IF(OR(N13="", P13=""), "", IF(N13>P13, "Fail Tape", IF(N13<=P13, "Pass", "")) )
H14: =IF(OR(Admin!E14="", Admin!D14=""), "", IF(Admin!C14="M", INDEX('Table B-1'!$C$9:$AX$31, MATCH(Admin!E14, 'Table B-1'!$A$9:$A$31, 0), MATCH(MIN(40,Admin!D14), 'Table B-1'!$C$4:$Z$4, 1)), IF(Admin!C14="F", INDEX('Table B-1'!$AA$9:$AX$31, MATCH(Admin!E14, 'Table B-1'!$A$9:$A$31, 0), MATCH(MIN(40,Admin!D14), 'Table B-1'!$AA$4:$AX$4, 1)), "" ) ) ) | I14: =IF(F14="", "", IF(F14>H14, "Needs Tape", IF(F14<=H14, "Pass", ""))) | M14: =IF(OR(ABS(J14-K14)>1, ABS(K14-L14)>1, ABS(J14-L14)>1), "Measurements differ by more than 1 inch", IF(OR(J14="", K14="", L14=""), "", ROUND(AVERAGE(J14, K14, L14)*2, 0)/2) ) | N14: =IF(OR(Admin!F14="", Admin!M14=""), "", IF(Admin!C14="M", IFERROR(INDEX('Figure B-1 Male'!$C$4:$AJ$164, MATCH(Admin!F14, 'Figure B-1 Male'!$B$4:$B$164, 0), MATCH(Admin!M14, 'Figure B-1 Male'!$C$3:$AJ$3, 1)) / 100, ""), IF(Admin!C14="F", IFERROR(INDEX('Figure B-2 Female'!$C$4:$AJ$164, MATCH(Admin!F14, 'Figure B-2 Female'!$B$4:$B$164, 0), MATCH(Admin!M14, 'Figure B-2 Female'!$C$3:$AJ$3, 1)) / 100, ""), "" ) ) ) | O14: =IF(OR(F14="", M14=""), "", IF(Admin!C14="M", (-26.97 - (0.12 * F14) + (1.99 * M14)) / 100, IF(Admin!C14="F", (-9.15 - (0.015 * F14) + (1.27 * M14)) / 100, "" ) ) ) | P14: =IF(OR(Admin!I14="Pass", Admin!I14=""), "", IF(Admin!D14="", "", IF(Admin!C14="M", INDEX('Table B-2'!$D$7:$D$30, MATCH(MIN(40, Admin!D14), 'Table B-2'!$C$7:$C$30, 0)), IF(Admin!C14="F", INDEX('Table B-2'!$F$7:$F$30, MATCH(MIN(40, Admin!D14), 'Table B-2'!$E$7:$E$30, 0)), "" ) ) ) ) | Q14: =IF(OR(N14="", P14=""), "", IF(N14>P14, "Fail Tape", IF(N14<=P14, "Pass", "")) )
H15: =IF(OR(Admin!E15="", Admin!D15=""), "", IF(Admin!C15="M", INDEX('Table B-1'!$C$9:$AX$31, MATCH(Admin!E15, 'Table B-1'!$A$9:$A$31, 0), MATCH(MIN(40,Admin!D15), 'Table B-1'!$C$4:$Z$4, 1)), IF(Admin!C15="F", INDEX('Table B-1'!$AA$9:$AX$31, MATCH(Admin!E15, 'Table B-1'!$A$9:$A$31, 0), MATCH(MIN(40,Admin!D15), 'Table B-1'!$AA$4:$AX$4, 1)), "" ) ) ) | I15: =IF(F15="", "", IF(F15>H15, "Needs Tape", IF(F15<=H15, "Pass", ""))) | M15: =IF(OR(ABS(J15-K15)>1, ABS(K15-L15)>1, ABS(J15-L15)>1), "Measurements differ by more than 1 inch", IF(OR(J15="", K15="", L15=""), "", ROUND(AVERAGE(J15, K15, L15)*2, 0)/2) ) | N15: =IF(OR(Admin!F15="", Admin!M15=""), "", IF(Admin!C15="M", IFERROR(INDEX('Figure B-1 Male'!$C$4:$AJ$164, MATCH(Admin!F15, 'Figure B-1 Male'!$B$4:$B$164, 0), MATCH(Admin!M15, 'Figure B-1 Male'!$C$3:$AJ$3, 1)) / 100, ""), IF(Admin!C15="F", IFERROR(INDEX('Figure B-2 Female'!$C$4:$AJ$164, MATCH(Admin!F15, 'Figure B-2 Female'!$B$4:$B$164, 0), MATCH(Admin!M15, 'Figure B-2 Female'!$C$3:$AJ$3, 1)) / 100, ""), "" ) ) ) | O15: =IF(OR(F15="", M15=""), "", IF(Admin!C15="M", (-26.97 - (0.12 * F15) + (1.99 * M15)) / 100, IF(Admin!C15="F", (-9.15 - (0.015 * F15) + (1.27 * M15)) / 100, "" ) ) ) | P15: =IF(OR(Admin!I15="Pass", Admin!I15=""), "", IF(Admin!D15="", "", IF(Admin!C15="M", INDEX('Table B-2'!$D$7:$D$30, MATCH(MIN(40, Admin!D15), 'Table B-2'!$C$7:$C$30, 0)), IF(Admin!C15="F", INDEX('Table B-2'!$F$7:$F$30, MATCH(MIN(40, Admin!D15), 'Table B-2'!$E$7:$E$30, 0)), "" ) ) ) ) | Q15: =IF(OR(N15="", P15=""), "", IF(N15>P15, "Fail Tape", IF(N15<=P15, "Pass", "")) )
H16: =IF(OR(Admin!E16="", Admin!D16=""), "", IF(Admin!C16="M", INDEX('Table B-1'!$C$9:$AX$31, MATCH(Admin!E16, 'Table B-1'!$A$9:$A$31, 0), MATCH(MIN(40,Admin!D16), 'Table B-1'!$C$4:$Z$4, 1)), IF(Admin!C16="F", INDEX('Table B-1'!$AA$9:$AX$31, MATCH(Admin!E16, 'Table B-1'!$A$9:$A$31, 0), MATCH(MIN(40,Admin!D16), 'Table B-1'!$AA$4:$AX$4, 1)), "" ) ) ) | I16: =IF(F16="", "", IF(F16>H16, "Needs Tape", IF(F16<=H16, "Pass", ""))) | M16: =IF(OR(ABS(J16-K16)>1, ABS(K16-L16)>1, ABS(J16-L16)>1), "Measurements differ by more than 1 inch", IF(OR(J16="", K16="", L16=""), "", ROUND(AVERAGE(J16, K16, L16)*2, 0)/2) ) | N16: =IF(OR(Admin!F16="", Admin!M16=""), "", IF(Admin!C16="M", IFERROR(INDEX('Figure B-1 Male'!$C$4:$AJ$164, MATCH(Admin!F16, 'Figure B-1 Male'!$B$4:$B$164, 0), MATCH(Admin!M16, 'Figure B-1 Male'!$C$3:$AJ$3, 1)) / 100, ""), IF(Admin!C16="F", IFERROR(INDEX('Figure B-2 Female'!$C$4:$AJ$164, MATCH(Admin!F16, 'Figure B-2 Female'!$B$4:$B$164, 0), MATCH(Admin!M16, 'Figure B-2 Female'!$C$3:$AJ$3, 1)) / 100, ""), "" ) ) ) | O16: =IF(OR(F16="", M16=""), "", IF(Admin!C16="M", (-26.97 - (0.12 * F16) + (1.99 * M16)) / 100, IF(Admin!C16="F", (-9.15 - (0.015 * F16) + (1.27 * M16)) / 100, "" ) ) ) | P16: =IF(OR(Admin!I16="Pass", Admin!I16=""), "", IF(Admin!D16="", "", IF(Admin!C16="M", INDEX('Table B-2'!$D$7:$D$30, MATCH(MIN(40, Admin!D16), 'Table B-2'!$C$7:$C$30, 0)), IF(Admin!C16="F", INDEX('Table B-2'!$F$7:$F$30, MATCH(MIN(40, Admin!D16), 'Table B-2'!$E$7:$E$30, 0)), "" ) ) ) ) | Q16: =IF(OR(N16="", P16=""), "", IF(N16>P16, "Fail Tape", IF(N16<=P16, "Pass", "")) )
H17: =IF(OR(Admin!E17="", Admin!D17=""), "", IF(Admin!C17="M", INDEX('Table B-1'!$C$9:$AX$31, MATCH(Admin!E17, 'Table B-1'!$A$9:$A$31, 0), MATCH(MIN(40,Admin!D17), 'Table B-1'!$C$4:$Z$4, 1)), IF(Admin!C17="F", INDEX('Table B-1'!$AA$9:$AX$31, MATCH(Admin!E17, 'Table B-1'!$A$9:$A$31, 0), MATCH(MIN(40,Admin!D17), 'Table B-1'!$AA$4:$AX$4, 1)), "" ) ) ) | I17: =IF(F17="", "", IF(F17>H17, "Needs Tape", IF(F17<=H17, "Pass", ""))) | M17: =IF(OR(ABS(J17-K17)>1, ABS(K17-L17)>1, ABS(J17-L17)>1), "Measurements differ by more than 1 inch", IF(OR(J17="", K17="", L17=""), "", ROUND(AVERAGE(J17, K17, L17)*2, 0)/2) ) | N17: =IF(OR(Admin!F17="", Admin!M17=""), "", IF(Admin!C17="M", IFERROR(INDEX('Figure B-1 Male'!$C$4:$AJ$164, MATCH(Admin!F17, 'Figure B-1 Male'!$B$4:$B$164, 0), MATCH(Admin!M17, 'Figure B-1 Male'!$C$3:$AJ$3, 1)) / 100, ""), IF(Admin!C17="F", IFERROR(INDEX('Figure B-2 Female'!$C$4:$AJ$164, MATCH(Admin!F17, 'Figure B-2 Female'!$B$4:$B$164, 0), MATCH(Admin!M17, 'Figure B-2 Female'!$C$3:$AJ$3, 1)) / 100, ""), "" ) ) ) | O17: =IF(OR(F17="", M17=""), "", IF(Admin!C17="M", (-26.97 - (0.12 * F17) + (1.99 * M17)) / 100, IF(Admin!C17="F", (-9.15 - (0.015 * F17) + (1.27 * M17)) / 100, "" ) ) ) | P17: =IF(OR(Admin!I17="Pass", Admin!I17=""), "", IF(Admin!D17="", "", IF(Admin!C17="M", INDEX('Table B-2'!$D$7:$D$30, MATCH(MIN(40, Admin!D17), 'Table B-2'!$C$7:$C$30, 0)), IF(Admin!C17="F", INDEX('Table B-2'!$F$7:$F$30, MATCH(MIN(40, Admin!D17), 'Table B-2'!$E$7:$E$30, 0)), "" ) ) ) ) | Q17: =IF(OR(N17="", P17=""), "", IF(N17>P17, "Fail Tape", IF(N17<=P17, "Pass", "")) )
H18: =IF(OR(Admin!E18="", Admin!D18=""), "", IF(Admin!C18="M", INDEX('Table B-1'!$C$9:$AX$31, MATCH(Admin!E18, 'Table B-1'!$A$9:$A$31, 0), MATCH(MIN(40,Admin!D18), 'Table B-1'!$C$4:$Z$4, 1)), IF(Admin!C18="F", INDEX('Table B-1'!$AA$9:$AX$31, MATCH(Admin!E18, 'Table B-1'!$A$9:$A$31, 0), MATCH(MIN(40,Admin!D18), 'Table B-1'!$AA$4:$AX$4, 1)), "" ) ) ) | I18: =IF(F18="", "", IF(F18>H18, "Needs Tape", IF(F18<=H18, "Pass", ""))) | M18: =IF(OR(ABS(J18-K18)>1, ABS(K18-L18)>1, ABS(J18-L18)>1), "Measurements differ by more than 1 inch", IF(OR(J18="", K18="", L18=""), "", ROUND(AVERAGE(J18, K18, L18)*2, 0)/2) ) | N18: =IF(OR(Admin!F18="", Admin!M18=""), "", IF(Admin!C18="M", IFERROR(INDEX('Figure B-1 Male'!$C$4:$AJ$164, MATCH(Admin!F18, 'Figure B-1 Male'!$B$4:$B$164, 0), MATCH(Admin!M18, 'Figure B-1 Male'!$C$3:$AJ$3, 1)) / 100, ""), IF(Admin!C18="F", IFERROR(INDEX('Figure B-2 Female'!$C$4:$AJ$164, MATCH(Admin!F18, 'Figure B-2 Female'!$B$4:$B$164, 0), MATCH(Admin!M18, 'Figure B-2 Female'!$C$3:$AJ$3, 1)) / 100, ""), "" ) ) ) | O18: =IF(OR(F18="", M18=""), "", IF(Admin!C18="M", (-26.97 - (0.12 * F18) + (1.99 * M18)) / 100, IF(Admin!C18="F", (-9.15 - (0.015 * F18) + (1.27 * M18)) / 100, "" ) ) ) | P18: =IF(OR(Admin!I18="Pass", Admin!I18=""), "", IF(Admin!D18="", "", IF(Admin!C18="M", INDEX('Table B-2'!$D$7:$D$30, MATCH(MIN(40, Admin!D18), 'Table B-2'!$C$7:$C$30, 0)), IF(Admin!C18="F", INDEX('Table B-2'!$F$7:$F$30, MATCH(MIN(40, Admin!D18), 'Table B-2'!$E$7:$E$30, 0)), "" ) ) ) ) | Q18: =IF(OR(N18="", P18=""), "", IF(N18>P18, "Fail Tape", IF(N18<=P18, "Pass", "")) )
... H104: =IF(OR(Admin!E104="", Admin!D104=""), "", IF(Admin!C104="M", INDEX('Table B-1'!$C$9:$AX$31, MATCH(Admin!E104, 'Table B-1'!$A$9:$A$31, 0), MATCH(MIN(40,Admin!D104), 'Table B-1'!$C$4:$Z$4, 1)), IF(Admin!C104="F", INDEX('Table B-1'!$AA$9:$AX$31, MATCH(Admin!E104, 'Table B-1'!$A$9:$A$31, 0), MATCH(MIN(40,Admin!D104), 'Table B-1'!$AA$4:$AX$4, 1)), "" ) ) ) | I104: =IF(F104="", "", IF(F104>H104, "Needs Tape", IF(F104<=H104, "Pass", ""))) | M104: =IF(OR(ABS(J104-K104)>1, ABS(K104-L104)>1, ABS(J104-L104)>1), "Measurements differ by more than 1 inch", IF(OR(J104="", K104="", L104=""), "", ROUND(AVERAGE(J104, K104, L104)*2, 0)/2) ) | N104: =IF(OR(Admin!F104="", Admin!M104=""), "", IF(Admin!C104="M", IFERROR(INDEX('Figure B-1 Male'!$C$4:$AJ$164, MATCH(Admin!F104, 'Figure B-1 Male'!$B$4:$B$164, 0), MATCH(Admin!M104, 'Figure B-1 Male'!$C$3:$AJ$3, 1)) / 100, ""), IF(Admin!C104="F", IFERROR(INDEX('Figure B-2 Female'!$C$4:$AJ$164, MATCH(Admin!F104, 'Figure B-2 Female'!$B$4:$B$164, 0), MATCH(Admin!M104, 'Figure B-2 Female'!$C$3:$AJ$3, 1)) / 100, ""), "" ) ) ) | O104: =IF(OR(F104="", M104=""), "", IF(Admin!C104="M", (-26.97 - (0.12 * F104) + (1.99 * M104)) / 100, IF(Admin!C104="F", (-9.15 - (0.015 * F104) + (1.27 * M104)) / 100, "" ) ) ) | P104: =IF(OR(Admin!I104="Pass", Admin!I104=""), "", IF(Admin!D104="", "", IF(Admin!C104="M", INDEX('Table B-2'!$D$7:$D$30, MATCH(MIN(40, Admin!D104), 'Table B-2'!$C$7:$C$30, 0)), IF(Admin!C104="F", INDEX('Table B-2'!$F$7:$F$30, MATCH(MIN(40, Admin!D104), 'Table B-2'!$E$7:$E$30, 0)), "" ) ) ) ) | Q104: =IF(OR(N104="", P104=""), "", IF(N104>P104, "Fail Tape", IF(N104<=P104, "Pass", "")) )
I105: =IF(F105="", "", IF(F105>H105, "Needs Tape", IF(F105<=H105, "Pass", ""))) | O105: =IF(OR(F105="", M105=""), "", IF(Admin!C105="M", (-26.97 - (0.12 * F105) + (1.99 * M105)) / 100, IF(Admin!C105="F", (-9.15 - (0.015 * F105) + (1.27 * M105)) / 100, "" ) ) ) | Q105: =IF(OR(N105="", P105=""), "", IF(N105>P105, "Fail Tape", IF(N105<=P105, "Pass", "")) )

Sheet Table B-1 (2)
C4: 17 | D4: 18 | E4: 19 | F4: 20 | G4: 21 | H4: 22 | I4: 23 | J4: 24 | K4: 25 | L4: 26 | M4: 27 | N4: 28 | O4: 29 | P4: 30 | Q4: 31 | R4: 32 | S4: 33 | T4: 34 | U4: 35 | V4: 36 | W4: 37 | X4: 38 | Y4: 39 | Z4: 40 | AA4: 17 | AB4: 18 | AC4: 19 | AD4: 20 | AE4: 21 | AF4: 22 | AG4: 23 | AH4: 24 | AI4: 25 | AJ4: 26 | AK4: 27 | AL4: 28 | AM4: 29 | AN4: 30 | AO4: 31 | AP4: 32 | AQ4: 33 | AR4: 34 | AS4: 35 | AT4: 36 | AU4: 37 | AV4: 38 | AW4: 39 | AX4: 40
A5: Table B-1
A6: Weight for height table (screening table weight)
A8: Height (inches) | B8: Minimum weight (pounds) | C8: 17-20 | D8: 17-20 | E8: 17-20 | F8: 17-20 | G8: 21-27 | H8: 21-27 | I8: 21-27 | J8: 21-27 | K8: 21-27 | L8: 21-27 | M8: 21-27 | N8: 28-39 | O8: 28-39 | P8: 28-39 | Q8: 28-39 | R8: 28-39 | S8: 28-39 | T8: 28-39 | U8: 28-39 | V8: 28-39 | W8: 28-39 | X8: 28-39 | Y8: 28-39 | Z8: 40 | AA8: 17-20 | AE8: 21-27 | AL8: 28-39 | AX8: 40
A9: 58 | B9: 91 | C9: - | D9: - | E9: - | F9: - | G9: - | H9: - | I9: - | J9: - | K9: - | L9: - | M9: - | N9: - | O9: - | P9: - | Q9: - | R9: - | S9: - | T9: - | U9: - | V9: - | W9: - | X9: - | Y9: - | Z9: - | AA9: 119 | AB9: 119 | AC9: 119 | AD9: 119 | AE9: 121 | AF9: 121 | AG9: 121 | AH9: 121 | AI9: 121 | AJ9: 121 | AK9: 121 | AL9: 122 | AM9: 122 | AN9: 122 | AO9: 122 | AP9: 122 | AQ9: 122 | AR9: 122 | AS9: 122 | AT9: 122 | AU9: 122 | AV9: 122 | AW9: 122 | AX9: 124
A10: 59 | B10: 94 | C10: - | D10: - | E10: - | F10: - | G10: - | H10: - | I10: - | J10: - | K10: - | L10: - | M10: - | N10: - | O10: - | P10: - | Q10: - | R10: - | S10: - | T10: - | U10: - | V10: - | W10: - | X10: - | Y10: - | Z10: - | AA10: 124 | AB10: 124 | AC10: 124 | AD10: 124 | AE10: 125 | AF10: 125 | AG10: 125 | AH10: 125 | AI10: 125 | AJ10: 125 | AK10: 125 | AL10: 126 | AM10: 126 | AN10: 126 | AO10: 126 | AP10: 126 | AQ10: 126 | AR10: 126 | AS10: 126 | AT10: 126 | AU10: 126 | AV10: 126 | AW10: 126 | AX10: 128
A11: 60 | B11: 97 | C11: 132 | D11: 132 | E11: 132 | F11: 132 | G11: 136 | H11: 136 | I11: 136 | J11: 136 | K11: 136 | L11: 136 | M11: 136 | N11: 139 | O11: 139 | P11: 139 | Q11: 139 | R11: 139 | S11: 139 | T11: 139 | U11: 139 | V11: 139 | W11: 139 | X11: 139 | Y11: 139 | Z11: 141 | AA11: 128 | AB11: 128 | AC11: 128 | AD11: 128 | AE11: 129 | AF11: 129 | AG11: 129 | AH11: 129 | AI11: 129 | AJ11: 129 | AK11: 129 | AL11: 131 | AM11: 131 | AN11: 131 | AO11: 131 | AP11: 131 | AQ11: 131 | AR11: 131 | AS11: 131 | AT11: 131 | AU11: 131 | AV11: 131 | AW11: 131 | AX11: 133
A12: 61 | B12: 100 | C12: 136 | D12: 136 | E12: 136 | F12: 136 | G12: 140 | H12: 140 | I12: 140 | J12: 140 | K12: 140 | L12: 140 | M12: 140 | N12: 144 | O12: 144 | P12: 144 | Q12: 144 | R12: 144 | S12: 144 | T12: 144 | U12: 144 | V12: 144 | W12: 144 | X12: 144 | Y12: 144 | Z12: 146 | AA12: 132 | AB12: 132 | AC12: 132 | AD12: 132 | AE12: 134 | AF12: 134 | AG12: 134 | AH12: 134 | AI12: 134 | AJ12: 134 | AK12: 134 | AL12: 135 | AM12: 135 | AN12: 135 | AO12: 135 | AP12: 135 | AQ12: 135 | AR12: 135 | AS12: 135 | AT12: 135 | AU12: 135 | AV12: 135 | AW12: 135 | AX12: 137
A13: 62 | B13: 104 | C13: 141 | D13: 141 | E13: 141 | F13: 141 | G13: 144 | H13: 144 | I13: 144 | J13: 144 | K13: 144 | L13: 144 | M13: 144 | N13: 148 | O13: 148 | P13: 148 | Q13: 148 | R13: 148 | S13: 148 | T13: 148 | U13: 148 | V13: 148 | W13: 148 | X13: 148 | Y13: 148 | Z13: 150 | AA13: 136 | AB13: 136 | AC13: 136 | AD13: 136 | AE13: 138 | AF13: 138 | AG13: 138 | AH13: 138 | AI13: 138 | AJ13: 138 | AK13: 138 | AL13: 140 | AM13: 140 | AN13: 140 | AO13: 140 | AP13: 140 | AQ13: 140 | AR13: 140 | AS13: 140 | AT13: 140 | AU13: 140 | AV13: 140 | AW13: 140 | AX13: 142
A14: 63 | B14: 107 | C14: 145 | D14: 145 | E14: 145 | F14: 145 | G14: 149 | H14: 149 | I14: 149 | J14: 149 | K14: 149 | L14: 149 | M14: 149 | N14: 153 | O14: 153 | P14: 153 | Q14: 153 | R14: 153 | S14: 153 | T14: 153 | U14: 153 | V14: 153 | W14: 153 | X14: 153 | Y14: 153 | Z14: 155 | AA14: 141 | AB14: 141 | AC14: 141 | AD14: 141 | AE14: 143 | AF14: 143 | AG14: 143 | AH14: 143 | AI14: 143 | AJ14: 143 | AK14: 143 | AL14: 144 | AM14: 144 | AN14: 144 | AO14: 144 | AP14: 144 | AQ14: 144 | AR14: 144 | AS14: 144 | AT14: 144 | AU14: 144 | AV14: 144 | AW14: 144 | AX14: 146
A15: 64 | B15: 110 | C15: 150 | D15: 150 | E15: 150 | F15: 150 | G15: 154 | H15: 154 | I15: 154 | J15: 154 | K15: 154 | L15: 154 | M15: 154 | N15: 158 | O15: 158 | P15: 158 | Q15: 158 | R15: 158 | S15: 158 | T15: 158 | U15: 158 | V15: 158 | W15: 158 | X15: 158 | Y15: 158 | Z15: 160 | AA15: 145 | AB15: 145 | AC15: 145 | AD15: 145 | AE15: 147 | AF15: 147 | AG15: 147 | AH15: 147 | AI15: 147 | AJ15: 147 | AK15: 147 | AL15: 149 | AM15: 149 | AN15: 149 | AO15: 149 | AP15: 149 | AQ15: 149 | AR15: 149 | AS15: 149 | AT15: 149 | AU15: 149 | AV15: 149 | AW15: 149 | AX15: 151
A16: 65 | B16: 114 | C16: 155 | D16: 155 | E16: 155 | F16: 155 | G16: 159 | H16: 159 | I16: 159 | J16: 159 | K16: 159 | L16: 159 | M16: 159 | N16: 163 | O16: 163 | P16: 163 | Q16: 163 | R16: 163 | S16: 163 | T16: 163 | U16: 163 | V16: 163 | W16: 163 | X16: 163 | Y16: 163 | Z16: 165 | AA16: 150 | AB16: 150 | AC16: 150 | AD16: 150 | AE16: 152 | AF16: 152 | AG16: 152 | AH16: 152 | AI16: 152 | AJ16: 152 | AK16: 152 | AL16: 154 | AM16: 154 | AN16: 154 | AO16: 154 | AP16: 154 | AQ16: 154 | AR16: 154 | AS16: 154 | AT16: 154 | AU16: 154 | AV16: 154 | AW16: 154 | AX16: 156
A17: 66 | B17: 117 | C17: 160 | D17: 160 | E17: 160 | F17: 160 | G17: 163 | H17: 163 | I17: 163 | J17: 163 | K17: 163 | L17: 163 | M17: 163 | N17: 168 | O17: 168 | P17: 168 | Q17: 168 | R17: 168 | S17: 168 | T17: 168 | U17: 168 | V17: 168 | W17: 168 | X17: 168 | Y17: 168 | Z17: 170 | AA17: 155 | AB17: 155 | AC17: 155 | AD17: 155 | AE17: 156 | AF17: 156 | AG17: 156 | AH17: 156 | AI17: 156 | AJ17: 156 | AK17: 156 | AL17: 158 | AM17: 158 | AN17: 158 | AO17: 158 | AP17: 158 | AQ17: 158 | AR17: 158 | AS17: 158 | AT17: 158 | AU17: 158 | AV17: 158 | AW17: 158 | AX17: 161
A18: 67 | B18: 121 | C18: 165 | D18: 165 | E18: 165 | F18: 165 | G18: 169 | H18: 169 | I18: 169 | J18: 169 | K18: 169 | L18: 169 | M18: 169 | N18: 174 | O18: 174 | P18: 174 | Q18: 174 | R18: 174 | S18: 174 | T18: 174 | U18: 174 | V18: 174 | W18: 174 | X18: 174 | Y18: 174 | Z18: 176 | AA18: 159 | AB18: 159 | AC18: 159 | AD18: 159 | AE18: 161 | AF18: 161 | AG18: 161 | AH18: 161 | AI18: 161 | AJ18: 161 | AK18: 161 | AL18: 163 | AM18: 163 | AN18: 163 | AO18: 163 | AP18: 163 | AQ18: 163 | AR18: 163 | AS18: 163 | AT18: 163 | AU18: 163 | AV18: 163 | AW18: 163 | AX18: 166
A19: 68 | B19: 125 | C19: 170 | D19: 170 | E19: 170 | F19: 170 | G19: 174 | H19: 174 | I19: 174 | J19: 174 | K19: 174 | L19: 174 | M19: 174 | N19: 179 | O19: 179 | P19: 179 | Q19: 179 | R19: 179 | S19: 179 | T19: 179 | U19: 179 | V19: 179 | W19: 179 | X19: 179 | Y19: 179 | Z19: 181 | AA19: 164 | AB19: 164 | AC19: 164 | AD19: 164 | AE19: 166 | AF19: 166 | AG19: 166 | AH19: 166 | AI19: 166 | AJ19: 166 | AK19: 166 | AL19: 168 | AM19: 168 | AN19: 168 | AO19: 168 | AP19: 168 | AQ19: 168 | AR19: 168 | AS19: 168 | AT19: 168 | AU19: 168 | AV19: 168 | AW19: 168 | AX19: 171
A20: 69 | B20: 128 | C20: 175 | D20: 175 | E20: 175 | F20: 175 | G20: 179 | H20: 179 | I20: 179 | J20: 179 | K20: 179 | L20: 179 | M20: 179 | N20: 184 | O20: 184 | P20: 184 | Q20: 184 | R20: 184 | S20: 184 | T20: 184 | U20: 184 | V20: 184 | W20: 184 | X20: 184 | Y20: 184 | Z20: 186 | AA20: 169 | AB20: 169 | AC20: 169 | AD20: 169 | AE20: 171 | AF20: 171 | AG20: 171 | AH20: 171 | AI20: 171 | AJ20: 171 | AK20: 171 | AL20: 173 | AM20: 173 | AN20: 173 | AO20: 173 | AP20: 173 | AQ20: 173 | AR20: 173 | AS20: 173 | AT20: 173 | AU20: 173 | AV20: 173 | AW20: 173 | AX20: 176
A21: 70 | B21: 132 | C21: 180 | D21: 180 | E21: 180 | F21: 180 | G21: 185 | H21: 185 | I21: 185 | J21: 185 | K21: 185 | L21: 185 | M21: 185 | N21: 189 | O21: 189 | P21: 189 | Q21: 189 | R21: 189 | S21: 189 | T21: 189 | U21: 189 | V21: 189 | W21: 189 | X21: 189 | Y21: 189 | Z21: 192 | AA21: 174 | AB21: 174 | AC21: 174 | AD21: 174 | AE21: 176 | AF21: 176 | AG21: 176 | AH21: 176 | AI21: 176 | AJ21: 176 | AK21: 176 | AL21: 178 | AM21: 178 | AN21: 178 | AO21: 178 | AP21: 178 | AQ21: 178 | AR21: 178 | AS21: 178 | AT21: 178 | AU21: 178 | AV21: 178 | AW21: 178 | AX21: 181
A22: 71 | B22: 136 | C22: 185 | D22: 185 | E22: 185 | F22: 185 | G22: 189 | H22: 189 | I22: 189 | J22: 189 | K22: 189 | L22: 189 | M22: 189 | N22: 194 | O22: 194 | P22: 194 | Q22: 194 | R22: 194 | S22: 194 | T22: 194 | U22: 194 | V22: 194 | W22: 194 | X22: 194 | Y22: 194 | Z22: 197 | AA22: 179 | AB22: 179 | AC22: 179 | AD22: 179 | AE22: 181 | AF22: 181 | AG22: 181 | AH22: 181 | AI22: 181 | AJ22: 181 | AK22: 181 | AL22: 183 | AM22: 183 | AN22: 183 | AO22: 183 | AP22: 183 | AQ22: 183 | AR22: 183 | AS22: 183 | AT22: 183 | AU22: 183 | AV22: 183 | AW22: 183 | AX22: 186
... A31: 80 | B31: 173 | C31: 234 | D31: 234 | E31: 234 | F31: 234 | G31: 240 | H31: 240 | I31: 240 | J31: 240 | K31: 240 | L31: 240 | M31: 240 | N31: 247 | O31: 247 | P31: 247 | Q31: 247 | R31: 247 | S31: 247 | T31: 247 | U31: 247 | V31: 247 | W31: 247 | X31: 247 | Y31: 247 | Z31: 250 | AA31: 227 | AB31: 227 | AC31: 227 | AD31: 227 | AE31: 230 | AF31: 230 | AG31: 230 | AH31: 230 | AI31: 230 | AJ31: 230 | AK31: 230 | AL31: 233 | AM31: 233 | AN31: 233 | AO31: 233 | AP31: 233 | AQ31: 233 | AR31: 233 | AS31: 233 | AT31: 233 | AU31: 233 | AV31: 233 | AW31: 233 | AX31: 236

Sheet Table B-1
C4: 17 | D4: 18 | E4: 19 | F4: 20 | G4: 21 | H4: 22 | I4: 23 | J4: 24 | K4: 25 | L4: 26 | M4: 27 | N4: 28 | O4: 29 | P4: 30 | Q4: 31 | R4: 32 | S4: 33 | T4: 34 | U4: 35 | V4: 36 | W4: 37 | X4: 38 | Y4: 39 | Z4: 40 | AA4: 17 | AB4: 18 | AC4: 19 | AD4: 20 | AE4: 21 | AF4: 22 | AG4: 23 | AH4: 24 | AI4: 25 | AJ4: 26 | AK4: 27 | AL4: 28 | AM4: 29 | AN4: 30 | AO4: 31 | AP4: 32 | AQ4: 33 | AR4: 34 | AS4: 35 | AT4: 36 | AU4: 37 | AV4: 38 | AW4: 39 | AX4: 40
A5: Table B-1
A6: Weight for height table (screening table weight)
A8: Height (inches) | B8: Minimum weight (pounds) | C8: 17-20 | D8: 17-20 | E8: 17-20 | F8: 17-20 | G8: 21-27 | H8: 21-27 | I8: 21-27 | J8: 21-27 | K8: 21-27 | L8: 21-27 | M8: 21-27 | N8: 28-39 | O8: 28-39 | P8: 28-39 | Q8: 28-39 | R8: 28-39 | S8: 28-39 | T8: 28-39 | U8: 28-39 | V8: 28-39 | W8: 28-39 | X8: 28-39 | Y8: 28-39 | Z8: 40 | AA8: 17-20 | AE8: 21-27 | AL8: 28-39 | AX8: 40
A9: 58 | B9: 91 | C9: - | D9: - | E9: - | F9: - | G9: - | H9: - | I9: - | J9: - | K9: - | L9: - | M9: - | N9: - | O9: - | P9: - | Q9: - | R9: - | S9: - | T9: - | U9: - | V9: - | W9: - | X9: - | Y9: - | Z9: - | AA9: 119 | AB9: 119 | AC9: 119 | AD9: 119 | AE9: 121 | AF9: 121 | AG9: 121 | AH9: 121 | AI9: 121 | AJ9: 121 | AK9: 121 | AL9: 122 | AM9: 122 | AN9: 122 | AO9: 122 | AP9: 122 | AQ9: 122 | AR9: 122 | AS9: 122 | AT9: 122 | AU9: 122 | AV9: 122 | AW9: 122 | AX9: 124
A10: 59 | B10: 94 | C10: - | D10: - | E10: - | F10: - | G10: - | H10: - | I10: - | J10: - | K10: - | L10: - | M10: - | N10: - | O10: - | P10: - | Q10: - | R10: - | S10: - | T10: - | U10: - | V10: - | W10: - | X10: - | Y10: - | Z10: - | AA10: 124 | AB10: 124 | AC10: 124 | AD10: 124 | AE10: 125 | AF10: 125 | AG10: 125 | AH10: 125 | AI10: 125 | AJ10: 125 | AK10: 125 | AL10: 126 | AM10: 126 | AN10: 126 | AO10: 126 | AP10: 126 | AQ10: 126 | AR10: 126 | AS10: 126 | AT10: 126 | AU10: 126 | AV10: 126 | AW10: 126 | AX10: 128
A11: 60 | B11: 97 | C11: 132 | D11: 132 | E11: 132 | F11: 132 | G11: 136 | H11: 136 | I11: 136 | J11: 136 | K11: 136 | L11: 136 | M11: 136 | N11: 139 | O11: 139 | P11: 139 | Q11: 139 | R11: 139 | S11: 139 | T11: 139 | U11: 139 | V11: 139 | W11: 139 | X11: 139 | Y11: 139 | Z11: 141 | AA11: 128 | AB11: 128 | AC11: 128 | AD11: 128 | AE11: 129 | AF11: 129 | AG11: 129 | AH11: 129 | AI11: 129 | AJ11: 129 | AK11: 129 | AL11: 131 | AM11: 131 | AN11: 131 | AO11: 131 | AP11: 131 | AQ11: 131 | AR11: 131 | AS11: 131 | AT11: 131 | AU11: 131 | AV11: 131 | AW11: 131 | AX11: 133
A12: 61 | B12: 100 | C12: 136 | D12: 136 | E12: 136 | F12: 136 | G12: 140 | H12: 140 | I12: 140 | J12: 140 | K12: 140 | L12: 140 | M12: 140 | N12: 144 | O12: 144 | P12: 144 | Q12: 144 | R12: 144 | S12: 144 | T12: 144 | U12: 144 | V12: 144 | W12: 144 | X12: 144 | Y12: 144 | Z12: 146 | AA12: 132 | AB12: 132 | AC12: 132 | AD12: 132 | AE12: 134 | AF12: 134 | AG12: 134 | AH12: 134 | AI12: 134 | AJ12: 134 | AK12: 134 | AL12: 135 | AM12: 135 | AN12: 135 | AO12: 135 | AP12: 135 | AQ12: 135 | AR12: 135 | AS12: 135 | AT12: 135 | AU12: 135 | AV12: 135 | AW12: 135 | AX12: 137
A13: 62 | B13: 104 | C13: 141 | D13: 141 | E13: 141 | F13: 141 | G13: 144 | H13: 144 | I13: 144 | J13: 144 | K13: 144 | L13: 144 | M13: 144 | N13: 148 | O13: 148 | P13: 148 | Q13: 148 | R13: 148 | S13: 148 | T13: 148 | U13: 148 | V13: 148 | W13: 148 | X13: 148 | Y13: 148 | Z13: 150 | AA13: 136 | AB13: 136 | AC13: 136 | AD13: 136 | AE13: 138 | AF13: 138 | AG13: 138 | AH13: 138 | AI13: 138 | AJ13: 138 | AK13: 138 | AL13: 140 | AM13: 140 | AN13: 140 | AO13: 140 | AP13: 140 | AQ13: 140 | AR13: 140 | AS13: 140 | AT13: 140 | AU13: 140 | AV13: 140 | AW13: 140 | AX13: 142
A14: 63 | B14: 107 | C14: 145 | D14: 145 | E14: 145 | F14: 145 | G14: 149 | H14: 149 | I14: 149 | J14: 149 | K14: 149 | L14: 149 | M14: 149 | N14: 153 | O14: 153 | P14: 153 | Q14: 153 | R14: 153 | S14: 153 | T14: 153 | U14: 153 | V14: 153 | W14: 153 | X14: 153 | Y14: 153 | Z14: 155 | AA14: 141 | AB14: 141 | AC14: 141 | AD14: 141 | AE14: 143 | AF14: 143 | AG14: 143 | AH14: 143 | AI14: 143 | AJ14: 143 | AK14: 143 | AL14: 144 | AM14: 144 | AN14: 144 | AO14: 144 | AP14: 144 | AQ14: 144 | AR14: 144 | AS14: 144 | AT14: 144 | AU14: 144 | AV14: 144 | AW14: 144 | AX14: 146
A15: 64 | B15: 110 | C15: 150 | D15: 150 | E15: 150 | F15: 150 | G15: 154 | H15: 154 | I15: 154 | J15: 154 | K15: 154 | L15: 154 | M15: 154 | N15: 158 | O15: 158 | P15: 158 | Q15: 158 | R15: 158 | S15: 158 | T15: 158 | U15: 158 | V15: 158 | W15: 158 | X15: 158 | Y15: 158 | Z15: 160 | AA15: 145 | AB15: 145 | AC15: 145 | AD15: 145 | AE15: 147 | AF15: 147 | AG15: 147 | AH15: 147 | AI15: 147 | AJ15: 147 | AK15: 147 | AL15: 149 | AM15: 149 | AN15: 149 | AO15: 149 | AP15: 149 | AQ15: 149 | AR15: 149 | AS15: 149 | AT15: 149 | AU15: 149 | AV15: 149 | AW15: 149 | AX15: 151
A16: 65 | B16: 114 | C16: 155 | D16: 155 | E16: 155 | F16: 155 | G16: 159 | H16: 159 | I16: 159 | J16: 159 | K16: 159 | L16: 159 | M16: 159 | N16: 163 | O16: 163 | P16: 163 | Q16: 163 | R16: 163 | S16: 163 | T16: 163 | U16: 163 | V16: 163 | W16: 163 | X16: 163 | Y16: 163 | Z16: 165 | AA16: 150 | AB16: 150 | AC16: 150 | AD16: 150 | AE16: 152 | AF16: 152 | AG16: 152 | AH16: 152 | AI16: 152 | AJ16: 152 | AK16: 152 | AL16: 154 | AM16: 154 | AN16: 154 | AO16: 154 | AP16: 154 | AQ16: 154 | AR16: 154 | AS16: 154 | AT16: 154 | AU16: 154 | AV16: 154 | AW16: 154 | AX16: 156
A17: 66 | B17: 117 | C17: 160 | D17: 160 | E17: 160 | F17: 160 | G17: 163 | H17: 163 | I17: 163 | J17: 163 | K17: 163 | L17: 163 | M17: 163 | N17: 168 | O17: 168 | P17: 168 | Q17: 168 | R17: 168 | S17: 168 | T17: 168 | U17: 168 | V17: 168 | W17: 168 | X17: 168 | Y17: 168 | Z17: 170 | AA17: 155 | AB17: 155 | AC17: 155 | AD17: 155 | AE17: 156 | AF17: 156 | AG17: 156 | AH17: 156 | AI17: 156 | AJ17: 156 | AK17: 156 | AL17: 158 | AM17: 158 | AN17: 158 | AO17: 158 | AP17: 158 | AQ17: 158 | AR17: 158 | AS17: 158 | AT17: 158 | AU17: 158 | AV17: 158 | AW17: 158 | AX17: 161
A18: 67 | B18: 121 | C18: 165 | D18: 165 | E18: 165 | F18: 165 | G18: 169 | H18: 169 | I18: 169 | J18: 169 | K18: 169 | L18: 169 | M18: 169 | N18: 174 | O18: 174 | P18: 174 | Q18: 174 | R18: 174 | S18: 174 | T18: 174 | U18: 174 | V18: 174 | W18: 174 | X18: 174 | Y18: 174 | Z18: 176 | AA18: 159 | AB18: 159 | AC18: 159 | AD18: 159 | AE18: 161 | AF18: 161 | AG18: 161 | AH18: 161 | AI18: 161 | AJ18: 161 | AK18: 161 | AL18: 163 | AM18: 163 | AN18: 163 | AO18: 163 | AP18: 163 | AQ18: 163 | AR18: 163 | AS18: 163 | AT18: 163 | AU18: 163 | AV18: 163 | AW18: 163 | AX18: 166
A19: 68 | B19: 125 | C19: 170 | D19: 170 | E19: 170 | F19: 170 | G19: 174 | H19: 174 | I19: 174 | J19: 174 | K19: 174 | L19: 174 | M19: 174 | N19: 179 | O19: 179 | P19: 179 | Q19: 179 | R19: 179 | S19: 179 | T19: 179 | U19: 179 | V19: 179 | W19: 179 | X19: 179 | Y19: 179 | Z19: 181 | AA19: 164 | AB19: 164 | AC19: 164 | AD19: 164 | AE19: 166 | AF19: 166 | AG19: 166 | AH19: 166 | AI19: 166 | AJ19: 166 | AK19: 166 | AL19: 168 | AM19: 168 | AN19: 168 | AO19: 168 | AP19: 168 | AQ19: 168 | AR19: 168 | AS19: 168 | AT19: 168 | AU19: 168 | AV19: 168 | AW19: 168 | AX19: 171
A20: 69 | B20: 128 | C20: 175 | D20: 175 | E20: 175 | F20: 175 | G20: 179 | H20: 179 | I20: 179 | J20: 179 | K20: 179 | L20: 179 | M20: 179 | N20: 184 | O20: 184 | P20: 184 | Q20: 184 | R20: 184 | S20: 184 | T20: 184 | U20: 184 | V20: 184 | W20: 184 | X20: 184 | Y20: 184 | Z20: 186 | AA20: 169 | AB20: 169 | AC20: 169 | AD20: 169 | AE20: 171 | AF20: 171 | AG20: 171 | AH20: 171 | AI20: 171 | AJ20: 171 | AK20: 171 | AL20: 173 | AM20: 173 | AN20: 173 | AO20: 173 | AP20: 173 | AQ20: 173 | AR20: 173 | AS20: 173 | AT20: 173 | AU20: 173 | AV20: 173 | AW20: 173 | AX20: 176
A21: 70 | B21: 132 | C21: 180 | D21: 180 | E21: 180 | F21: 180 | G21: 185 | H21: 185 | I21: 185 | J21: 185 | K21: 185 | L21: 185 | M21: 185 | N21: 189 | O21: 189 | P21: 189 | Q21: 189 | R21: 189 | S21: 189 | T21: 189 | U21: 189 | V21: 189 | W21: 189 | X21: 189 | Y21: 189 | Z21: 192 | AA21: 174 | AB21: 174 | AC21: 174 | AD21: 174 | AE21: 176 | AF21: 176 | AG21: 176 | AH21: 176 | AI21: 176 | AJ21: 176 | AK21: 176 | AL21: 178 | AM21: 178 | AN21: 178 | AO21: 178 | AP21: 178 | AQ21: 178 | AR21: 178 | AS21: 178 | AT21: 178 | AU21: 178 | AV21: 178 | AW21: 178 | AX21: 181
A22: 71 | B22: 136 | C22: 185 | D22: 185 | E22: 185 | F22: 185 | G22: 189 | H22: 189 | I22: 189 | J22: 189 | K22: 189 | L22: 189 | M22: 189 | N22: 194 | O22: 194 | P22: 194 | Q22: 194 | R22: 194 | S22: 194 | T22: 194 | U22: 194 | V22: 194 | W22: 194 | X22: 194 | Y22: 194 | Z22: 197 | AA22: 179 | AB22: 179 | AC22: 179 | AD22: 179 | AE22: 181 | AF22: 181 | AG22: 181 | AH22: 181 | AI22: 181 | AJ22: 181 | AK22: 181 | AL22: 183 | AM22: 183 | AN22: 183 | AO22: 183 | AP22: 183 | AQ22: 183 | AR22: 183 | AS22: 183 | AT22: 183 | AU22: 183 | AV22: 183 | AW22: 183 | AX22: 186
... A31: 80 | B31: 173 | C31: 234 | D31: 234 | E31: 234 | F31: 234 | G31: 240 | H31: 240 | I31: 240 | J31: 240 | K31: 240 | L31: 240 | M31: 240 | N31: 247 | O31: 247 | P31: 247 | Q31: 247 | R31: 247 | S31: 247 | T31: 247 | U31: 247 | V31: 247 | W31: 247 | X31: 247 | Y31: 247 | Z31: 250 | AA31: 227 | AB31: 227 | AC31: 227 | AD31: 227 | AE31: 230 | AF31: 230 | AG31: 230 | AH31: 230 | AI31: 230 | AJ31: 230 | AK31: 230 | AL31: 233 | AM31: 233 | AN31: 233 | AO31: 233 | AP31: 233 | AQ31: 233 | AR31: 233 | AS31: 233 | AT31: 233 | AU31: 233 | AV31: 233 | AW31: 233 | AX31: 236

Sheet Table B-2
A1: Table B – 2
A2: Maximum allowable percent body fat standards
A3: Age Group | B3: 17 - 20 | C3: Male (% Body Fat) | D3: 0.2 | E3: Female (% Body Fat) | F3: 0.3
A4: Age Group | B4: 21 - 27 | C4: Male (% Body Fat) | D4: 0.22 | E4: Female (% Body Fat) | F4: 0.32
A5: Age Group | B5: 28 - 39 | C5: Male (% Body Fat) | D5: 0.24 | E5: Female (% Body Fat) | F5: 0.34
A6: Age Group | B6: 40 and older | C6: Male (% Body Fat) | D6: 0.26 | E6: Female (% Body Fat) | F6: 0.36
C7: 17 | D7: 0.2 | E7: 17 | F7: 0.3
C8: 18 | D8: 0.2 | E8: 18 | F8: 0.3
C9: 19 | D9: 0.2 | E9: 19 | F9: 0.3
C10: 20 | D10: 0.2 | E10: 20 | F10: 0.3
C11: 21 | D11: 0.22 | E11: 21 | F11: 0.32
C12: 22 | D12: 0.22 | E12: 22 | F12: 0.32
C13: 23 | D13: 0.22 | E13: 23 | F13: 0.32
C14: 24 | D14: 0.22 | E14: 24 | F14: 0.32
C15: 25 | D15: 0.22 | E15: 25 | F15: 0.32
C16: 26 | D16: 0.22 | E16: 26 | F16: 0.32
C17: 27 | D17: 0.22 | E17: 27 | F17: 0.32
C18: 28 | D18: 0.24 | E18: 28 | F18: 0.34
... C30: 40 | D30: 0.26 | E30: 40 | F30: 0.36

Sheet Figure B-1 Male
C1: 2023 ARMY CALCULATED PERCENT (%) BODY FAT - MALE
C2: WAIST CIRCUMFERENCE (inches)
C3: 27 | D3: 27.5 | E3: 28 | F3: 28.5 | G3: 29 | H3: 29.5 | I3: 30 | J3: 30.5 | K3: 31 | L3: 31.5 | M3: 32 | N3: 32.5 | O3: 33 | P3: 33.5 | Q3: 34 | R3: 34.5 | S3: 35 | T3: 35.5 | U3: 36 | V3: 36.5 | W3: 37 | X3: 37.5 | Y3: 38 | Z3: 38.5 | AA3: 39 | AB3: 39.5 | AC3: 40 | AD3: 40.5 | AE3: 41 | AF3: 41.5 | AG3: 42 | AH3: 42.5 | AI3: 43 | AJ3: 43.5
A4: BODY WEIGHT (pounds) BODY WEIGHT (pounds) BODY WEIGHT (pounds) BODY WEIGHT (pounds) BODY WEIGHT (pounds) BODY WEIGHT (pounds) | B4: 90 | C4: 16 | D4: 17 | E4: 18 | F4: 19 | G4: 20 | H4: 21 | I4: 22 | J4: 23 | K4: 24 | L4: 25 | M4: 26 | N4: 27 | O4: 28 | P4: 29 | Q4: 30 | R4: 31 | S4: 32 | T4: 33 | U4: 34 | V4: 35 | W4: 36 | X4: 37 | Y4: 38 | Z4: 39 | AA4: 40 | AB4: 41 | AC4: 42 | AD4: 43 | AE4: 44 | AF4: 45 | AG4: 46 | AH4: 47 | AI4: 48 | AJ4: 49
B5: 91 | C5: 16 | D5: 17 | E5: 18 | F5: 19 | G5: 20 | H5: 21 | I5: 22 | J5: 23 | K5: 24 | L5: 25 | M5: 26 | N5: 27 | O5: 28 | P5: 29 | Q5: 30 | R5: 31 | S5: 32 | T5: 33 | U5: 34 | V5: 35 | W5: 36 | X5: 37 | Y5: 38 | Z5: 39 | AA5: 40 | AB5: 41 | AC5: 42 | AD5: 43 | AE5: 44 | AF5: 45 | AG5: 46 | AH5: 47 | AI5: 48 | AJ5: 49
B6: 92 | C6: 16 | D6: 17 | E6: 18 | F6: 19 | G6: 20 | H6: 21 | I6: 22 | J6: 23 | K6: 24 | L6: 25 | M6: 26 | N6: 27 | O6: 28 | P6: 29 | Q6: 30 | R6: 31 | S6: 32 | T6: 33 | U6: 34 | V6: 35 | W6: 36 | X6: 37 | Y6: 38 | Z6: 39 | AA6: 40 | AB6: 41 | AC6: 42 | AD6: 43 | AE6: 44 | AF6: 45 | AG6: 46 | AH6: 47 | AI6: 48 | AJ6: 49
B7: 93 | C7: 16 | D7: 17 | E7: 18 | F7: 19 | G7: 20 | H7: 21 | I7: 22 | J7: 23 | K7: 24 | L7: 25 | M7: 26 | N7: 27 | O7: 28 | P7: 29 | Q7: 30 | R7: 31 | S7: 32 | T7: 33 | U7: 34 | V7: 35 | W7: 36 | X7: 36 | Y7: 37 | Z7: 38 | AA7: 39 | AB7: 40 | AC7: 41 | AD7: 42 | AE7: 43 | AF7: 44 | AG7: 45 | AH7: 46 | AI7: 47 | AJ7: 48
B8: 94 | C8: 15 | D8: 16 | E8: 17 | F8: 18 | G8: 19 | H8: 20 | I8: 21 | J8: 22 | K8: 23 | L8: 24 | M8: 25 | N8: 26 | O8: 27 | P8: 28 | Q8: 29 | R8: 30 | S8: 31 | T8: 32 | U8: 33 | V8: 34 | W8: 35 | X8: 36 | Y8: 37 | Z8: 38 | AA8: 39 | AB8: 40 | AC8: 41 | AD8: 42 | AE8: 43 | AF8: 44 | AG8: 45 | AH8: 46 | AI8: 47 | AJ8: 48
B9: 95 | C9: 15 | D9: 16 | E9: 17 | F9: 18 | G9: 19 | H9: 20 | I9: 21 | J9: 22 | K9: 23 | L9: 24 | M9: 25 | N9: 26 | O9: 27 | P9: 28 | Q9: 29 | R9: 30 | S9: 31 | T9: 32 | U9: 33 | V9: 34 | W9: 35 | X9: 36 | Y9: 37 | Z9: 38 | AA9: 39 | AB9: 40 | AC9: 41 | AD9: 42 | AE9: 43 | AF9: 44 | AG9: 45 | AH9: 46 | AI9: 47 | AJ9: 48
B10: 96 | C10: 15 | D10: 16 | E10: 17 | F10: 18 | G10: 19 | H10: 20 | I10: 21 | J10: 22 | K10: 23 | L10: 24 | M10: 25 | N10: 26 | O10: 27 | P10: 28 | Q10: 29 | R10: 30 | S10: 31 | T10: 32 | U10: 33 | V10: 34 | W10: 35 | X10: 36 | Y10: 37 | Z10: 38 | AA10: 39 | AB10: 40 | AC10: 41 | AD10: 42 | AE10: 43 | AF10: 44 | AG10: 45 | AH10: 46 | AI10: 47 | AJ10: 48
B11: 97 | C11: 15 | D11: 16 | E11: 17 | F11: 18 | G11: 19 | H11: 20 | I11: 21 | J11: 22 | K11: 23 | L11: 24 | M11: 25 | N11: 26 | O11: 27 | P11: 28 | Q11: 29 | R11: 30 | S11: 31 | T11: 32 | U11: 33 | V11: 34 | W11: 35 | X11: 36 | Y11: 37 | Z11: 38 | AA11: 39 | AB11: 40 | AC11: 41 | AD11: 42 | AE11: 43 | AF11: 44 | AG11: 45 | AH11: 46 | AI11: 47 | AJ11: 48
B12: 98 | C12: 15 | D12: 16 | E12: 17 | F12: 18 | G12: 19 | H12: 20 | I12: 21 | J12: 22 | K12: 23 | L12: 24 | M12: 25 | N12: 26 | O12: 27 | P12: 28 | Q12: 29 | R12: 30 | S12: 31 | T12: 32 | U12: 33 | V12: 34 | W12: 35 | X12: 36 | Y12: 37 | Z12: 38 | AA12: 39 | AB12: 40 | AC12: 41 | AD12: 42 | AE12: 43 | AF12: 44 | AG12: 45 | AH12: 46 | AI12: 47 | AJ12: 48
B13: 99 | C13: 15 | D13: 16 | E13: 17 | F13: 18 | G13: 19 | H13: 20 | I13: 21 | J13: 22 | K13: 23 | L13: 24 | M13: 25 | N13: 26 | O13: 27 | P13: 28 | Q13: 29 | R13: 30 | S13: 31 | T13: 32 | U13: 33 | V13: 34 | W13: 35 | X13: 36 | Y13: 37 | Z13: 38 | AA13: 39 | AB13: 40 | AC13: 41 | AD13: 42 | AE13: 43 | AF13: 44 | AG13: 45 | AH13: 46 | AI13: 47 | AJ13: 48
B14: 100 | C14: 15 | D14: 16 | E14: 17 | F14: 18 | G14: 19 | H14: 20 | I14: 21 | J14: 22 | K14: 23 | L14: 24 | M14: 25 | N14: 26 | O14: 27 | P14: 28 | Q14: 29 | R14: 30 | S14: 31 | T14: 32 | U14: 33 | V14: 34 | W14: 35 | X14: 36 | Y14: 37 | Z14: 38 | AA14: 39 | AB14: 40 | AC14: 41 | AD14: 42 | AE14: 43 | AF14: 44 | AG14: 45 | AH14: 46 | AI14: 47 | AJ14: 48
B15: 101 | C15: 15 | D15: 16 | E15: 17 | F15: 18 | G15: 19 | H15: 20 | I15: 21 | J15: 22 | K15: 23 | L15: 24 | M15: 25 | N15: 26 | O15: 27 | P15: 28 | Q15: 29 | R15: 30 | S15: 31 | T15: 32 | U15: 33 | V15: 34 | W15: 35 | X15: 36 | Y15: 37 | Z15: 38 | AA15: 39 | AB15: 40 | AC15: 41 | AD15: 42 | AE15: 43 | AF15: 43 | AG15: 44 | AH15: 45 | AI15: 46 | AJ15: 47
B16: 102 | C16: 15 | D16: 16 | E16: 17 | F16: 18 | G16: 18 | H16: 19 | I16: 20 | J16: 21 | K16: 22 | L16: 23 | M16: 24 | N16: 25 | O16: 26 | P16: 27 | Q16: 28 | R16: 29 | S16: 30 | T16: 31 | U16: 32 | V16: 33 | W16: 34 | X16: 35 | Y16: 36 | Z16: 37 | AA16: 38 | AB16: 39 | AC16: 40 | AD16: 41 | AE16: 42 | AF16: 43 | AG16: 44 | AH16: 45 | AI16: 46 | AJ16: 47
... B57: 143 | C57: 10 | D57: 11 | E57: 12 | F57: 13 | G57: 14 | H57: 15 | I57: 16 | J57: 17 | K57: 18 | L57: 19 | M57: 20 | N57: 21 | O57: 22 | P57: 23 | Q57: 24 | R57: 25 | S57: 26 | T57: 27 | U57: 28 | V57: 29 | W57: 30 | X57: 30 | Y57: 31 | Z57: 32 | AA57: 33 | AB57: 34 | AC57: 35 | AD57: 36 | AE57: 37 | AF57: 38 | AG57: 39 | AH57: 40 | AI57: 41 | AJ57: 42
B58: 144 | C58: <10 | D58: 10 | E58: 11 | F58: 12 | G58: 13 | H58: 14 | I58: 15 | J58: 16 | K58: 17 | L58: 18 | M58: 19 | N58: 20 | O58: 21 | P58: 22 | Q58: 23 | R58: 24 | S58: 25 | T58: 26 | U58: 27 | V58: 28 | W58: 29 | X58: 30 | Y58: 31 | Z58: 32 | AA58: 33 | AB58: 34 | AC58: 35 | AD58: 36 | AE58: 37 | AF58: 38 | AG58: 39 | AH58: 40 | AI58: 41 | AJ58: 42
B59: 145 | C59: <10 | D59: 10 | E59: 11 | F59: 12 | G59: 13 | H59: 14 | I59: 15 | J59: 16 | K59: 17 | L59: 18 | M59: 19 | N59: 20 | O59: 21 | P59: 22 | Q59: 23 | R59: 24 | S59: 25 | T59: 26 | U59: 27 | V59: 28 | W59: 29 | X59: 30 | Y59: 31 | Z59: 32 | AA59: 33 | AB59: 34 | AC59: 35 | AD59: 36 | AE59: 37 | AF59: 38 | AG59: 39 | AH59: 40 | AI59: 41 | AJ59: 42
B60: 146 | C60: <10 | D60: 10 | E60: 11 | F60: 12 | G60: 13 | H60: 14 | I60: 15 | J60: 16 | K60: 17 | L60: 18 | M60: 19 | N60: 20 | O60: 21 | P60: 22 | Q60: 23 | R60: 24 | S60: 25 | T60: 26 | U60: 27 | V60: 28 | W60: 29 | X60: 30 | Y60: 31 | Z60: 32 | AA60: 33 | AB60: 34 | AC60: 35 | AD60: 36 | AE60: 37 | AF60: 38 | AG60: 39 | AH60: 40 | AI60: 41 | AJ60: 42
B61: 147 | C61: <10 | D61: 10 | E61: 11 | F61: 12 | G61: 13 | H61: 14 | I61: 15 | J61: 16 | K61: 17 | L61: 18 | M61: 19 | N61: 20 | O61: 21 | P61: 22 | Q61: 23 | R61: 24 | S61: 25 | T61: 26 | U61: 27 | V61: 28 | W61: 29 | X61: 30 | Y61: 31 | Z61: 32 | AA61: 33 | AB61: 34 | AC61: 35 | AD61: 36 | AE61: 37 | AF61: 38 | AG61: 39 | AH61: 40 | AI61: 41 | AJ61: 42
B62: 148 | C62: <10 | D62: 10 | E62: 11 | F62: 12 | G62: 13 | H62: 14 | I62: 15 | J62: 16 | K62: 17 | L62: 18 | M62: 19 | N62: 20 | O62: 21 | P62: 22 | Q62: 23 | R62: 24 | S62: 25 | T62: 26 | U62: 27 | V62: 28 | W62: 29 | X62: 30 | Y62: 31 | Z62: 32 | AA62: 33 | AB62: 34 | AC62: 35 | AD62: 36 | AE62: 37 | AF62: 38 | AG62: 39 | AH62: 40 | AI62: 41 | AJ62: 42
B63: 149 | C63: <10 | D63: 10 | E63: 11 | F63: 12 | G63: 13 | H63: 14 | I63: 15 | J63: 16 | K63: 17 | L63: 18 | M63: 19 | N63: 20 | O63: 21 | P63: 22 | Q63: 23 | R63: 24 | S63: 25 | T63: 26 | U63: 27 | V63: 28 | W63: 29 | X63: 30 | Y63: 31 | Z63: 32 | AA63: 33 | AB63: 34 | AC63: 35 | AD63: 36 | AE63: 37 | AF63: 38 | AG63: 39 | AH63: 40 | AI63: 41 | AJ63: 42
B64: 150 | C64: <10 | D64: 10 | E64: 11 | F64: 12 | G64: 13 | H64: 14 | I64: 15 | J64: 16 | K64: 17 | L64: 18 | M64: 19 | N64: 20 | O64: 21 | P64: 22 | Q64: 23 | R64: 24 | S64: 25 | T64: 26 | U64: 27 | V64: 28 | W64: 29 | X64: 30 | Y64: 31 | Z64: 32 | AA64: 33 | AB64: 34 | AC64: 35 | AD64: 36 | AE64: 37 | AF64: 38 | AG64: 39 | AH64: 40 | AI64: 41 | AJ64: 42
B65: 151 | C65: <10 | D65: 10 | E65: 11 | F65: 12 | G65: 13 | H65: 14 | I65: 15 | J65: 16 | K65: 17 | L65: 18 | M65: 19 | N65: 20 | O65: 21 | P65: 22 | Q65: 23 | R65: 24 | S65: 25 | T65: 26 | U65: 27 | V65: 28 | W65: 29 | X65: 30 | Y65: 31 | Z65: 32 | AA65: 33 | AB65: 34 | AC65: 35 | AD65: 36 | AE65: 36 | AF65: 37 | AG65: 38 | AH65: 39 | AI65: 40 | AJ65: 41
B66: 152 | C66: <10 | D66: 10 | E66: 11 | F66: 12 | G66: 13 | H66: 13 | I66: 14 | J66: 15 | K66: 16 | L66: 17 | M66: 18 | N66: 19 | O66: 20 | P66: 21 | Q66: 22 | R66: 23 | S66: 24 | T66: 25 | U66: 26 | V66: 27 | W66: 28 | X66: 29 | Y66: 30 | Z66: 31 | AA66: 32 | AB66: 33 | AC66: 34 | AD66: 35 | AE66: 36 | AF66: 37 | AG66: 38 | AH66: 39 | AI66: 40 | AJ66: 41
B67: 153 | C67: <10 | D67: <10 | E67: 10 | F67: 11 | G67: 12 | H67: 13 | I67: 14 | J67: 15 | K67: 16 | L67: 17 | M67: 18 | N67: 19 | O67: 20 | P67: 21 | Q67: 22 | R67: 23 | S67: 24 | T67: 25 | U67: 26 | V67: 27 | W67: 28 | X67: 29 | Y67: 30 | Z67: 31 | AA67: 32 | AB67: 33 | AC67: 34 | AD67: 35 | AE67: 36 | AF67: 37 | AG67: 38 | AH67: 39 | AI67: 40 | AJ67: 41
B68: 154 | C68: <10 | D68: <10 | E68: 10 | F68: 11 | G68: 12 | H68: 13 | I68: 14 | J68: 15 | K68: 16 | L68: 17 | M68: 18 | N68: 19 | O68: 20 | P68: 21 | Q68: 22 | R68: 23 | S68: 24 | T68: 25 | U68: 26 | V68: 27 | W68: 28 | X68: 29 | Y68: 30 | Z68: 31 | AA68: 32 | AB68: 33 | AC68: 34 | AD68: 35 | AE68: 36 | AF68: 37 | AG68: 38 | AH68: 39 | AI68: 40 | AJ68: 41
B69: 155 | C69: <10 | D69: <10 | E69: 10 | F69: 11 | G69: 12 | H69: 13 | I69: 14 | J69: 15 | K69: 16 | L69: 17 | M69: 18 | N69: 19 | O69: 20 | P69: 21 | Q69: 22 | R69: 23 | S69: 24 | T69: 25 | U69: 26 | V69: 27 | W69: 28 | X69: 29 | Y69: 30 | Z69: 31 | AA69: 32 | AB69: 33 | AC69: 34 | AD69: 35 | AE69: 36 | AF69: 37 | AG69: 38 | AH69: 39 | AI69: 40 | AJ69: 41
B70: 156 | C70: <10 | D70: <10 | E70: 10 | F70: 11 | G70: 12 | H70: 13 | I70: 14 | J70: 15 | K70: 16 | L70: 17 | M70: 18 | N70: 19 | O70: 20 | P70: 21 | Q70: 22 | R70: 23 | S70: 24 | T70: 25 | U70: 26 | V70: 27 | W70: 28 | X70: 29 | Y70: 30 | Z70: 31 | AA70: 32 | AB70: 33 | AC70: 34 | AD70: 35 | AE70: 36 | AF70: 37 | AG70: 38 | AH70: 39 | AI70: 40 | AJ70: 41
B71: 157 | C71: <10 | D71: <10 | E71: 10 | F71: 11 | G71: 12 | H71: 13 | I71: 14 | J71: 15 | K71: 16 | L71: 17 | M71: 18 | N71: 19 | O71: 20 | P71: 21 | Q71: 22 | R71: 23 | S71: 24 | T71: 25 | U71: 26 | V71: 27 | W71: 28 | X71: 29 | Y71: 30 | Z71: 31 | AA71: 32 | AB71: 33 | AC71: 34 | AD71: 35 | AE71: 36 | AF71: 37 | AG71: 38 | AH71: 39 | AI71: 40 | AJ71: 41
B72: 158 | C72: <10 | D72: <10 | E72: 10 | F72: 11 | G72: 12 | H72: 13 | I72: 14 | J72: 15 | K72: 16 | L72: 17 | M72: 18 | N72: 19 | O72: 20 | P72: 21 | Q72: 22 | R72: 23 | S72: 24 | T72: 25 | U72: 26 | V72: 27 | W72: 28 | X72: 29 | Y72: 30 | Z72: 31 | AA72: 32 | AB72: 33 | AC72: 34 | AD72: 35 | AE72: 36 | AF72: 37 | AG72: 38 | AH72: 39 | AI72: 40 | AJ72: 41
B73: 159 | C73: <10 | D73: <10 | E73: 10 | F73: 11 | G73: 12 | H73: 13 | I73: 14 | J73: 15 | K73: 16 | L73: 17 | M73: 18 | N73: 19 | O73: 20 | P73: 21 | Q73: 22 | R73: 23 | S73: 24 | T73: 25 | U73: 26 | V73: 27 | W73: 28 | X73: 29 | Y73: 30 | Z73: 31 | AA73: 32 | AB73: 33 | AC73: 34 | AD73: 35 | AE73: 36 | AF73: 37 | AG73: 38 | AH73: 39 | AI73: 40 | AJ73: 41
B74: 160 | C74: <10 | D74: <10 | E74: 10 | F74: 11 | G74: 12 | H74: 13 | I74: 14 | J74: 15 | K74: 16 | L74: 17 | M74: 18 | N74: 19 | O74: 20 | P74: 20 | Q74: 21 | R74: 22 | S74: 23 | T74: 24 | U74: 25 | V74: 26 | W74: 27 | X74: 28 | Y74: 29 | Z74: 30 | AA74: 31 | AB74: 32 | AC74: 33 | AD74: 34 | AE74: 35 | AF74: 36 | AG74: 37 | AH74: 38 | AI74: 39 | AJ74: 40
B75: 161 | C75: <10 | D75: <10 | E75: <10 | F75: 10 | G75: 11 | H75: 12 | I75: 13 | J75: 14 | K75: 15 | L75: 16 | M75: 17 | N75: 18 | O75: 19 | P75: 20 | Q75: 21 | R75: 22 | S75: 23 | T75: 24 | U75: 25 | V75: 26 | W75: 27 | X75: 28 | Y75: 29 | Z75: 30 | AA75: 31 | AB75: 32 | AC75: 33 | AD75: 34 | AE75: 35 | AF75: 36 | AG75: 37 | AH75: 38 | AI75: 39 | AJ75: 40
B76: 162 | C76: <10 | D76: <10 | E76: <10 | F76: 10 | G76: 11 | H76: 12 | I76: 13 | J76: 14 | K76: 15 | L76: 16 | M76: 17 | N76: 18 | O76: 19 | P76: 20 | Q76: 21 | R76: 22 | S76: 23 | T76: 24 | U76: 25 | V76: 26 | W76: 27 | X76: 28 | Y76: 29 | Z76: 30 | AA76: 31 | AB76: 32 | AC76: 33 | AD76: 34 | AE76: 35 | AF76: 36 | AG76: 37 | AH76: 38 | AI76: 39 | AJ76: 40
B77: 163 | C77: <10 | D77: <10 | E77: <10 | F77: 10 | G77: 11 | H77: 12 | I77: 13 | J77: 14 | K77: 15 | L77: 16 | M77: 17 | N77: 18 | O77: 19 | P77: 20 | Q77: 21 | R77: 22 | S77: 23 | T77: 24 | U77: 25 | V77: 26 | W77: 27 | X77: 28 | Y77: 29 | Z77: 30 | AA77: 31 | AB77: 32 | AC77: 33 | AD77: 34 | AE77: 35 | AF77: 36 | AG77: 37 | AH77: 38 | AI77: 39 | AJ77: 40
B78: 164 | C78: <10 | D78: <10 | E78: <10 | F78: 10 | G78: 11 | H78: 12 | I78: 13 | J78: 14 | K78: 15 | L78: 16 | M78: 17 | N78: 18 | O78: 19 | P78: 20 | Q78: 21 | R78: 22 | S78: 23 | T78: 24 | U78: 25 | V78: 26 | W78: 27 | X78: 28 | Y78: 29 | Z78: 30 | AA78: 31 | AB78: 32 | AC78: 33 | AD78: 34 | AE78: 35 | AF78: 36 | AG78: 37 | AH78: 38 | AI78: 39 | AJ78: 40
B79: 165 | C79: <10 | D79: <10 | E79: <10 | F79: 10 | G79: 11 | H79: 12 | I79: 13 | J79: 14 | K79: 15 | L79: 16 | M79: 17 | N79: 18 | O79: 19 | P79: 20 | Q79: 21 | R79: 22 | S79: 23 | T79: 24 | U79: 25 | V79: 26 | W79: 27 | X79: 28 | Y79: 29 | Z79: 30 | AA79: 31 | AB79: 32 | AC79: 33 | AD79: 34 | AE79: 35 | AF79: 36 | AG79: 37 | AH79: 38 | AI79: 39 | AJ79: 40
B80: 166 | C80: <10 | D80: <10 | E80: <10 | F80: 10 | G80: 11 | H80: 12 | I80: 13 | J80: 14 | K80: 15 | L80: 16 | M80: 17 | N80: 18 | O80: 19 | P80: 20 | Q80: 21 | R80: 22 | S80: 23 | T80: 24 | U80: 25 | V80: 26 | W80: 27 | X80: 28 | Y80: 29 | Z80: 30 | AA80: 31 | AB80: 32 | AC80: 33 | AD80: 34 | AE80: 35 | AF80: 36 | AG80: 37 | AH80: 38 | AI80: 39 | AJ80: 40
...

Sheet Figure B-2 Female
C1: 2023 ARMY CALCULATED PERCENT (%) BODY FAT - FEMALE
C2: WAIST CIRCUMFERENCE (inches)
C3: 25 | D3: 25.5 | E3: 26 | F3: 26.5 | G3: 27 | H3: 27.5 | I3: 28 | J3: 28.5 | K3: 29 | L3: 29.5 | M3: 30 | N3: 30.5 | O3: 31 | P3: 31.5 | Q3: 32 | R3: 32.5 | S3: 33 | T3: 33.5 | U3: 34 | V3: 34.5 | W3: 35 | X3: 35.5 | Y3: 36 | Z3: 36.5 | AA3: 37 | AB3: 37.5 | AC3: 38 | AD3: 38.5 | AE3: 39 | AF3: 39.5 | AG3: 40 | AH3: 40.5 | AI3: 41 | AJ3: 41.5
A4: BODY WEIGHT (pounds) BODY WEIGHT (pounds) BODY WEIGHT (pounds) BODY WEIGHT (pounds) BODY WEIGHT (pounds) BODY WEIGHT (pounds) | B4: 90 | C4: 21 | D4: 22 | E4: 23 | F4: 23 | G4: 24 | H4: 24 | I4: 25 | J4: 26 | K4: 26 | L4: 27 | M4: 28 | N4: 28 | O4: 29 | P4: 30 | Q4: 30 | R4: 31 | S4: 31 | T4: 32 | U4: 33 | V4: 33 | W4: 34 | X4: 35 | Y4: 35 | Z4: 36 | AA4: 36 | AB4: 37 | AC4: 38 | AD4: 38 | AE4: 39 | AF4: 40 | AG4: 40 | AH4: 41 | AI4: 42 | AJ4: 42
B5: 91 | C5: 21 | D5: 22 | E5: 23 | F5: 23 | G5: 24 | H5: 24 | I5: 25 | J5: 26 | K5: 26 | L5: 27 | M5: 28 | N5: 28 | O5: 29 | P5: 29 | Q5: 30 | R5: 31 | S5: 31 | T5: 32 | U5: 33 | V5: 33 | W5: 34 | X5: 35 | Y5: 35 | Z5: 36 | AA5: 36 | AB5: 37 | AC5: 38 | AD5: 38 | AE5: 39 | AF5: 40 | AG5: 40 | AH5: 41 | AI5: 42 | AJ5: 42
B6: 92 | C6: 21 | D6: 22 | E6: 22 | F6: 23 | G6: 24 | H6: 24 | I6: 25 | J6: 26 | K6: 26 | L6: 27 | M6: 28 | N6: 28 | O6: 29 | P6: 29 | Q6: 30 | R6: 31 | S6: 31 | T6: 32 | U6: 33 | V6: 33 | W6: 34 | X6: 35 | Y6: 35 | Z6: 36 | AA6: 36 | AB6: 37 | AC6: 38 | AD6: 38 | AE6: 39 | AF6: 40 | AG6: 40 | AH6: 41 | AI6: 42 | AJ6: 42
B7: 93 | C7: 21 | D7: 22 | E7: 22 | F7: 23 | G7: 24 | H7: 24 | I7: 25 | J7: 26 | K7: 26 | L7: 27 | M7: 28 | N7: 28 | O7: 29 | P7: 29 | Q7: 30 | R7: 31 | S7: 31 | T7: 32 | U7: 33 | V7: 33 | W7: 34 | X7: 35 | Y7: 35 | Z7: 36 | AA7: 36 | AB7: 37 | AC7: 38 | AD7: 38 | AE7: 39 | AF7: 40 | AG7: 40 | AH7: 41 | AI7: 42 | AJ7: 42
B8: 94 | C8: 21 | D8: 22 | E8: 22 | F8: 23 | G8: 24 | H8: 24 | I8: 25 | J8: 26 | K8: 26 | L8: 27 | M8: 28 | N8: 28 | O8: 29 | P8: 29 | Q8: 30 | R8: 31 | S8: 31 | T8: 32 | U8: 33 | V8: 33 | W8: 34 | X8: 35 | Y8: 35 | Z8: 36 | AA8: 36 | AB8: 37 | AC8: 38 | AD8: 38 | AE8: 39 | AF8: 40 | AG8: 40 | AH8: 41 | AI8: 42 | AJ8: 42
B9: 95 | C9: 21 | D9: 22 | E9: 22 | F9: 23 | G9: 24 | H9: 24 | I9: 25 | J9: 26 | K9: 26 | L9: 27 | M9: 28 | N9: 28 | O9: 29 | P9: 29 | Q9: 30 | R9: 31 | S9: 31 | T9: 32 | U9: 33 | V9: 33 | W9: 34 | X9: 35 | Y9: 35 | Z9: 36 | AA9: 36 | AB9: 37 | AC9: 38 | AD9: 38 | AE9: 39 | AF9: 40 | AG9: 40 | AH9: 41 | AI9: 41 | AJ9: 42
B10: 96 | C10: 21 | D10: 22 | E10: 22 | F10: 23 | G10: 24 | H10: 24 | I10: 25 | J10: 26 | K10: 26 | L10: 27 | M10: 28 | N10: 28 | O10: 29 | P10: 29 | Q10: 30 | R10: 31 | S10: 31 | T10: 32 | U10: 33 | V10: 33 | W10: 34 | X10: 34 | Y10: 35 | Z10: 36 | AA10: 36 | AB10: 37 | AC10: 38 | AD10: 38 | AE10: 39 | AF10: 40 | AG10: 40 | AH10: 41 | AI10: 41 | AJ10: 42
B11: 97 | C11: 21 | D11: 22 | E11: 22 | F11: 23 | G11: 24 | H11: 24 | I11: 25 | J11: 26 | K11: 26 | L11: 27 | M11: 27 | N11: 28 | O11: 29 | P11: 29 | Q11: 30 | R11: 31 | S11: 31 | T11: 32 | U11: 33 | V11: 33 | W11: 34 | X11: 34 | Y11: 35 | Z11: 36 | AA11: 36 | AB11: 37 | AC11: 38 | AD11: 38 | AE11: 39 | AF11: 40 | AG11: 40 | AH11: 41 | AI11: 41 | AJ11: 42
B12: 98 | C12: 21 | D12: 22 | E12: 22 | F12: 23 | G12: 24 | H12: 24 | I12: 25 | J12: 26 | K12: 26 | L12: 27 | M12: 27 | N12: 28 | O12: 29 | P12: 29 | Q12: 30 | R12: 31 | S12: 31 | T12: 32 | U12: 33 | V12: 33 | W12: 34 | X12: 34 | Y12: 35 | Z12: 36 | AA12: 36 | AB12: 37 | AC12: 38 | AD12: 38 | AE12: 39 | AF12: 40 | AG12: 40 | AH12: 41 | AI12: 41 | AJ12: 42
